Workbook

Sheet README
A1: Open-source swarm software landscape: technology and document inventory
A2: Complete edition, 15 September 2026. Sources: the project's report (markdown and PDF versions, identical content) and slide deck.
A4: Tabs
A5: Report changes: every correction, clarification, update, and relevant addition found while collecting documents, with the report section it belongs in, the evidence, and a suggested edit.
A6: Technologies: one row per technology, with the dimensions from the report and a live count of documents found.
A7: Documents: one row per document. Filled so far for the pilot (10 technologies plus 2 found alongside), batch 1 (the report's recommended stack and core swarm frameworks), batch 2 (simulators, network co-simulation bridges, and learning environments), batch 3 (commercial products, middleware, and tools), batch 4 (Section 10 research papers and hardware), and the added technologies. All technologies are now covered; four have no reliable URL yet. Remaining technologies show Pending in the Technologies tab.
A8: Top 3: every technology with documents has its three best starting documents ranked 1–3 in the Documents 'Top 3 rank' column. Filter that column to non-blank for a first-pass scrape list. Ranking favors definitive architecture papers and official documentation over marketing and release notes.
A9: Techniques: techniques and methods, one authoritative reference each. Many are canonical papers or standards added from general knowledge; the Verified column says which.
A10: Rows shaded green in Technologies are technologies not in the report that turned up during collection (for example ROS-NetSim, FlyNetSim, SynchroSim, CARLA-Air). Each has a matching entry in Report changes.
A11: Scrape methods: what each value in the Documents 'Scrape method' column means, for building the scraper.
A13: Column definitions
A14: Layers: L0 motors and firmware; L1 single-vehicle autonomy; L2 middleware and communication; L3 multi-vehicle coordination; L4 mission, operator, and fleet management; L5 simulation and test; L6 learning and adaptation.
... A36: ResearchGate, IEEE Xplore, and ACM Digital Library block or restrict automated downloads; prefer arXiv or open-access copies.

Sheet Report changes
A1: Change ID | B1: Type | C1: Report section | D1: Technology | E1: What changed or what to add | F1: Evidence | G1: Suggested action
A2: C001 | B2: Correction | C2: §2.5, §3.1 (OFFSET row) | D2: DARPA OFFSET systems | E2: Report attributes CCAST to Northrop Grumman; the CCAST paper credits Raytheon BBN and SIFT. Northrop Grumman was the other integrator. | F2: arXiv 2307.16788 acknowledgments | G2: Change to 'Raytheon BBN (CCAST) and Northrop Grumman'.
A3: C002 | B3: Correction | C3: §2.5, §3 table | D3: OpenAMASE | E3: License is the Air Force Open Source Agreement 1.0 (with required email registration of use), not the NASA agreement. | F3: github.com/afrl-rq/OpenAMASE README | G3: Fix license; note registration requirement for closed deliverables (§7 criterion 3).
A4: C003 | B4: Correction | C4: §2.5, §3 table | D4: OpenUxAS | E4: Commits as recent as April 2026 and SPARK formal proofs in the test suite; report describes sporadic commits. | F4: github.com/afrl-rq organization listing and OpenUxAS README | G4: Update activity; cite SPARK proofs in §6 and §10.3 Blocker 8 (assurance).
A5: C004 | B5: Correction | C5: §2.6 table, §3.2 | D5: Cosys-AirSim | E5: README says the repository is provided as is and will not be actively updated; report calls it a living fork. | F5: Cosys-AirSim README | G5: Mark as low activity; point to Project AirSim and CARLA-Air.
A6: C005 | B6: Correction | C6: §2.1, §7 | D6: Crazyflie firmware | E6: README forks state LGPL-3.0; report says GPL-3. | F6: crazyflie-firmware README forks | G6: Confirm in upstream LICENSE; LGPL relaxes the closed-deliverable concern.
A7: C006 | B7: Correction | C7: §3.2 (Webots row), §2.6 | D7: Webots | E7: Apache-2.0 license; report leaves license unstated. | F7: cyberbotics/webots README (fork copy) | G7: Add license.
A8: C007 | B8: Clarification | C8: §6 (Learning) | D8: SwarmSync / SwarmModelPatch | E8: These distribute software and model updates across a heterogeneous swarm (the SwarmUpdate framework); they are not decentralized training. | F8: arXiv 2503.13784 | G8: Reword to 'propagating software and model updates'; also cite under §4 gap 6 (fleet logistics, over-the-air updates).
A9: C008 | B9: Update | C9: §2.7, §8 Option A | D9: NVIDIA Cosmos | E9: Cosmos 3 launched 1 June 2026 as a unified omnimodal model family; repositories moved to github.com/NVIDIA/Cosmos. | F9: cosmos-transfer2.5 and cosmos-predict README notices | G9: Update Cosmos description and links; Cosmos 3 also generates actions and policies.
A10: C009 | B10: Update | C10: §2.7 | D10: NVIDIA Isaac Sim | E10: Isaac Sim 6.0 is an Early Developer Release (docs banner: incomplete; binaries at general availability); 6.0.1 release notes dated June 2026. Isaac Lab 3.0 beta targets 6.0. | F10: Isaac Sim docs banner; Isaac Lab releases | G10: Qualify 6.0 as early developer release.
A11: C010 | B11: Update | C11: §2.6, §2.7 | D11: OmniDrones; Pegasus Simulator | E11: Official OmniDrones targets Isaac Sim 4.1; Pegasus v5.1.0 targets Isaac Sim 5.1. Neither confirmed on 6.0. | F11: OmniDrones README; Pegasus README | G11: Add version caveat to Isaac-based recommendations.
A12: C011 | B12: Update | C12: §2.2, §8 Option A, §9.4 | D12: PX4 Zenoh bridge | E12: PX4 ships a native Zenoh bridge (zenoh-pico client and zenohd router) as an alternative to uXRCE-DDS; PX4 still recommends DDS for most users. | F12: docs.px4.io ROS 2 User Guide | G12: Add as an option in Option A Layer 2 and the §9.4 middleware bullet.
... A39: C038 | B39: Addition | C39: §2.3 (Aerostack2) | D39: Aerostack2 + Pegasus + Isaac Sim | E39: Aerostack2 publishes a worked Pegasus/Isaac Sim integration project. | F39: github.com/aerostack2/project_pegasus_isaac_sim | G39: Note path for perception-grade aerial swarm simulation.

Sheet Technologies
A1: Technology | B1: Category | C1: Layers | D1: License | E1: Domains | F1: Open source or commercial | G1: Maintenance status | H1: Popularity | I1: In report | J1: In slide deck | K1: Batch | L1: Documents found | M1: Top 3 found | N1: Notes
A2: PX4 Autopilot | B2: Autopilots and vehicle firmware | C2: L0–L1 | D2: BSD-3-Clause | E2: Air (thinner ground/water) | F2: Open source | G2: Active | H2: ★★★★ | I2: Yes | J2: Yes | K2: Pilot | L2: =COUNTIF(Documents!$B:$B,A2) | M2: =COUNTIFS(Documents!$B:$B,A2,Documents!$J:$J,">0")
A3: ArduPilot | B3: Autopilots and vehicle firmware | C3: L0–L1 | D3: GPL-3.0 | E3: Air, ground, surface, underwater | F3: Open source | G3: Active | H3: ★★★★ | I3: Yes | J3: Yes | K3: Batch 1 | L3: =COUNTIF(Documents!$B:$B,A3) | M3: =COUNTIFS(Documents!$B:$B,A3,Documents!$J:$J,">0")
A4: Skybrush ArduPilot fork | B4: Autopilots and vehicle firmware | C4: L0 | D4: GPL-3.0 | E4: Air | F4: Open source | G4: Active | I4: Yes | J4: Yes | K4: Batch 1 | L4: =COUNTIF(Documents!$B:$B,A4) | M4: =COUNTIFS(Documents!$B:$B,A4,Documents!$J:$J,">0")
A5: Crazyflie firmware | B5: Autopilots and vehicle firmware | C5: L0–L1 | D5: LGPL-3.0 per README forks (report said GPL-3; confirm) | E5: Air (palm-sized) | F5: Open source | G5: Active | I5: Yes | J5: Yes | K5: Batch 3 | L5: =COUNTIF(Documents!$B:$B,A5) | M5: =COUNTIFS(Documents!$B:$B,A5,Documents!$J:$J,">0")
A6: Betaflight | B6: Autopilots and vehicle firmware | C6: L0 | D6: Not stated in report | E6: Air | F6: Open source | G6: Not assessed | I6: Yes | J6: No | K6: Batch 3 | L6: =COUNTIF(Documents!$B:$B,A6) | M6: =COUNTIFS(Documents!$B:$B,A6,Documents!$J:$J,">0")
A7: iNav | B7: Autopilots and vehicle firmware | C7: L0 | D7: Not stated in report | E7: Air | F7: Open source | G7: Not assessed | I7: Yes | J7: No | K7: Batch 3 | L7: =COUNTIF(Documents!$B:$B,A7) | M7: =COUNTIFS(Documents!$B:$B,A7,Documents!$J:$J,">0")
A8: PX4 DDS bridge (uXRCE-DDS) | B8: Autopilots and vehicle firmware | C8: L2 | D8: BSD-3-Clause | E8: Air, ground, water | F8: Open source | G8: Active | I8: Yes | J8: Yes | K8: Batch 3 | L8: =COUNTIF(Documents!$B:$B,A8) | M8: =COUNTIFS(Documents!$B:$B,A8,Documents!$J:$J,">0")
A9: MRS UAV System | B9: Single-vehicle autonomy and navigation | C9: L1–L3 | D9: BSD-3-Clause | E9: Air (multirotor) | F9: Open source | G9: Active (ROS 2 port in progress) | H9: ★★ | I9: Yes | J9: Yes | K9: Batch 1 | L9: =COUNTIF(Documents!$B:$B,A9) | M9: =COUNTIFS(Documents!$B:$B,A9,Documents!$J:$J,">0")
A10: Nav2 | B10: Single-vehicle autonomy and navigation | C10: L1 | D10: Apache-2.0 | E10: Ground | F10: Open source | G10: Active | I10: Yes | J10: Yes | K10: Batch 1 | L10: =COUNTIF(Documents!$B:$B,A10) | M10: =COUNTIFS(Documents!$B:$B,A10,Documents!$J:$J,">0")
A11: MOOS-IvP | B11: Single-vehicle autonomy and navigation | C11: L1–L5 | D11: GPL / LGPL | E11: Water (surface and underwater) | F11: Open source | G11: Active | H11: ★ (large real user base) | I11: Yes | J11: Yes | K11: Batch 1 | L11: =COUNTIF(Documents!$B:$B,A11) | M11: =COUNTIFS(Documents!$B:$B,A11,Documents!$J:$J,">0")
A12: Autoware | B12: Single-vehicle autonomy and navigation | C12: L1 | D12: Not stated in report | E12: Ground (road vehicles) | F12: Open source | G12: Not assessed | I12: Yes | J12: No | K12: Batch 3 | L12: =COUNTIF(Documents!$B:$B,A12) | M12: =COUNTIFS(Documents!$B:$B,A12,Documents!$J:$J,">0")
A13: NVIDIA Isaac ROS | B13: Single-vehicle autonomy and navigation | C13: L1–L2 | D13: Apache-2.0 plus NVIDIA terms on some models | E13: Air, ground | F13: Open source (mixed terms) | G13: Active | H13: ★★ | I13: Yes | J13: Yes | K13: Batch 1 | L13: =COUNTIF(Documents!$B:$B,A13) | M13: =COUNTIFS(Documents!$B:$B,A13,Documents!$J:$J,">0")
A14: cuVSLAM | B14: Single-vehicle autonomy and navigation | C14: L1 | D14: NVIDIA terms | E14: Air, ground | F14: Open source (mixed terms) | G14: Active | I14: Yes | J14: Yes | K14: Batch 1 | L14: =COUNTIF(Documents!$B:$B,A14) | M14: =COUNTIFS(Documents!$B:$B,A14,Documents!$J:$J,">0")
A15: nvblox | B15: Single-vehicle autonomy and navigation | C15: L1 | D15: Not stated in report | E15: Air, ground | F15: Open source (mixed terms) | G15: Active | I15: Yes | J15: Yes | K15: Batch 1 | L15: =COUNTIF(Documents!$B:$B,A15) | M15: =COUNTIFS(Documents!$B:$B,A15,Documents!$J:$J,">0")
A16: NITROS | B16: Middleware, messaging, and networking | C16: L2 | D16: Not stated in report | E16: Air, ground | F16: Open source (mixed terms) | G16: Active | I16: Yes | J16: Yes | K16: Batch 3 | L16: =COUNTIF(Documents!$B:$B,A16) | M16: =COUNTIFS(Documents!$B:$B,A16,Documents!$J:$J,">0")
A17: ROS 2 (Robot Operating System 2) | B17: Middleware, messaging, and networking | C17: L2 | D17: Apache-2.0 | E17: All | F17: Open source | G17: Active | I17: Yes | J17: Yes | K17: Batch 1 | L17: =COUNTIF(Documents!$B:$B,A17) | M17: =COUNTIFS(Documents!$B:$B,A17,Documents!$J:$J,">0")
A18: ROS 1 | B18: Middleware, messaging, and networking | C18: L2 | D18: Not stated in report | E18: All | F18: Open source | G18: End of life | I18: Yes | J18: No | K18: Batch 3 | L18: =COUNTIF(Documents!$B:$B,A18) | M18: =COUNTIFS(Documents!$B:$B,A18,Documents!$J:$J,">0")
A19: DDS (Data Distribution Service) | B19: Middleware, messaging, and networking | C19: L2 | D19: Standard (multiple implementations) | E19: All | F19: Open standard | G19: Active | I19: Yes | J19: Yes | K19: Batch 1 | L19: =COUNTIF(Documents!$B:$B,A19) | M19: =COUNTIFS(Documents!$B:$B,A19,Documents!$J:$J,">0")
A20: Zenoh / rmw_zenoh | B20: Middleware, messaging, and networking | C20: L2 | D20: Not stated in report | E20: All | F20: Open source | G20: Active | I20: Yes | J20: Yes | K20: Batch 1 | L20: =COUNTIF(Documents!$B:$B,A20) | M20: =COUNTIFS(Documents!$B:$B,A20,Documents!$J:$J,">0")
A21: SROS2 (Secure ROS 2) | B21: Middleware, messaging, and networking | C21: L2 | D21: Not stated in report | E21: All | F21: Open source | G21: Active | I21: Yes | J21: Yes | K21: Batch 3 | L21: =COUNTIF(Documents!$B:$B,A21) | M21: =COUNTIFS(Documents!$B:$B,A21,Documents!$J:$J,">0")
A22: micro-ROS | B22: Middleware, messaging, and networking | C22: L0–L2 | D22: Not stated in report | E22: All (microcontroller vehicles) | F22: Open source | G22: Active | I22: Yes | J22: Yes | K22: Batch 1 | L22: =COUNTIF(Documents!$B:$B,A22) | M22: =COUNTIFS(Documents!$B:$B,A22,Documents!$J:$J,">0")
A23: MOOS | B23: Middleware, messaging, and networking | C23: L2 | D23: GPL / LGPL | E23: Water | F23: Open source | G23: Active | I23: Yes | J23: Yes | K23: Batch 3 | L23: =COUNTIF(Documents!$B:$B,A23) | M23: =COUNTIFS(Documents!$B:$B,A23,Documents!$J:$J,">0")
A24: MAVLink | B24: Middleware, messaging, and networking | C24: L2 | D24: Permissive | E24: Air, ground, water | F24: Open standard | G24: Active | I24: Yes | J24: Yes | K24: Batch 1 | L24: =COUNTIF(Documents!$B:$B,A24) | M24: =COUNTIFS(Documents!$B:$B,A24,Documents!$J:$J,">0")
A25: MAVSDK | B25: Middleware, messaging, and networking | C25: L2 | D25: Permissive | E25: Air, ground, water | F25: Open source | G25: Active | I25: Yes | J25: Yes | K25: Batch 1 | L25: =COUNTIF(Documents!$B:$B,A25) | M25: =COUNTIFS(Documents!$B:$B,A25,Documents!$J:$J,">0")
... A35: Time-sensitive networking | B35: Middleware, messaging, and networking | C35: L2 | D35: Standard (IEEE 802.1) | E35: n/a | F35: Open standard | G35: Active | I35: Yes | J35: Yes | K35: Batch 3 | L35: =COUNTIF(Documents!$B:$B,A35) | M35: =COUNTIFS(Documents!$B:$B,A35,Documents!$J:$J,">0")
A36: Aerostack2 | B36: Multi-vehicle coordination frameworks | C36: L1–L4 | D36: BSD-3-Clause | E36: Air | F36: Open source | G36: Active (built on ROS 2 Humble) | H36: ★★ | I36: Yes | J36: Yes | K36: Pilot | L36: =COUNTIF(Documents!$B:$B,A36) | M36: =COUNTIFS(Documents!$B:$B,A36,Documents!$J:$J,">0")
A37: CTU-MRS swarm packages | B37: Multi-vehicle coordination frameworks | C37: L3 | D37: BSD-3-Clause | E37: Air (multirotor) | F37: Open source | G37: Active | I37: Yes | J37: Yes | K37: Batch 1 | L37: =COUNTIF(Documents!$B:$B,A37) | M37: =COUNTIFS(Documents!$B:$B,A37,Documents!$J:$J,">0")
A38: Crazyswarm2 | B38: Multi-vehicle coordination frameworks | C38: L1–L3 | D38: MIT | E38: Air (palm-sized, indoor) | F38: Open source | G38: Active | H38: ★★ | I38: Yes | J38: Yes | K38: Batch 1 | L38: =COUNTIF(Documents!$B:$B,A38) | M38: =COUNTIFS(Documents!$B:$B,A38,Documents!$J:$J,">0")
A39: CrazyChoir | B39: Multi-vehicle coordination frameworks | C39: L3 | D39: GPL-3.0 | E39: Air (palm-sized) | F39: Open source | G39: Not assessed | I39: Yes | J39: Yes | K39: Batch 1 | L39: =COUNTIF(Documents!$B:$B,A39) | M39: =COUNTIFS(Documents!$B:$B,A39,Documents!$J:$J,">0")
A40: ChoiRbot | B40: Multi-vehicle coordination frameworks | C40: L3 | D40: GPL-3.0 | E40: Ground, air | F40: Open source | G40: Not assessed | H40: ★ | I40: Yes | J40: Yes | K40: Batch 1 | L40: =COUNTIF(Documents!$B:$B,A40) | M40: =COUNTIFS(Documents!$B:$B,A40,Documents!$J:$J,">0")
A41: ROS2swarm | B41: Multi-vehicle coordination frameworks | C41: L3 | D41: Check (not confirmed) | E41: Ground | F41: Open source | G41: Pinned to old ROS 2 releases | H41: ★ | I41: Yes | J41: Yes | K41: Batch 1 | L41: =COUNTIF(Documents!$B:$B,A41) | M41: =COUNTIFS(Documents!$B:$B,A41,Documents!$J:$J,">0")
A42: Buzz | B42: Multi-vehicle coordination frameworks | C42: L3 | D42: MIT | E42: Any (mostly simulated) | F42: Open source | G42: Lightly maintained | H42: ★★ | I42: Yes | J42: Yes | K42: Batch 1 | L42: =COUNTIF(Documents!$B:$B,A42) | M42: =COUNTIFS(Documents!$B:$B,A42,Documents!$J:$J,">0")
A43: SwarmBox | B43: Multi-vehicle coordination frameworks | C43: L3–L5 | D43: MIT | E43: Air | F43: Open source | G43: New (2026), early-stage | H43: ★ | I43: Yes | J43: Yes | K43: Batch 1 | L43: =COUNTIF(Documents!$B:$B,A43) | M43: =COUNTIFS(Documents!$B:$B,A43,Documents!$J:$J,">0")
A44: Open-RMF (Open Robotics Middleware Framework) | B44: Multi-vehicle coordination frameworks | C44: L3–L4 | D44: Apache-2.0 | E44: Ground (indoor fleets) | F44: Open source | G44: Active | H44: ★★ | I44: Yes | J44: Yes | K44: Batch 1 | L44: =COUNTIF(Documents!$B:$B,A44) | M44: =COUNTIFS(Documents!$B:$B,A44,Documents!$J:$J,">0")
A45: OpenUxAS (Open Unmanned Systems Autonomy Services) | B45: Multi-vehicle coordination frameworks | C45: L3–L4 | D45: NASA Open Source Agreement (confirm in repository LICENSE) | E45: Air | F45: Open source | G45: Commits as recent as April 2026 (report said dormant) | H45: ★ | I45: Yes | J45: Yes | K45: Batch 1 | L45: =COUNTIF(Documents!$B:$B,A45) | M45: =COUNTIFS(Documents!$B:$B,A45,Documents!$J:$J,">0")
A46: CoFlyers | B46: Multi-vehicle coordination frameworks | C46: L3 (prototyping) | D46: Not stated in report | E46: Air | F46: Open source | G46: Not assessed | I46: Yes | J46: No | K46: No URL found | L46: =COUNTIF(Documents!$B:$B,A46) | M46: =COUNTIFS(Documents!$B:$B,A46,Documents!$J:$J,">0")
A47: Skybrush Server / Live / Studio | B47: Mission, operator, and fleet tools | C47: L4 | D47: GPL-3.0 (paid tiers closed) | E47: Air | F47: Open core | G47: Active | H47: ★★ | I47: Yes | J47: Yes | K47: Batch 1 | L47: =COUNTIF(Documents!$B:$B,A47) | M47: =COUNTIFS(Documents!$B:$B,A47,Documents!$J:$J,">0")
A48: QGroundControl | B48: Mission, operator, and fleet tools | C48: L4 | D48: Not stated in report | E48: Air, ground, water | F48: Open source | G48: Active | I48: Yes | J48: Yes | K48: Batch 3 | L48: =COUNTIF(Documents!$B:$B,A48) | M48: =COUNTIFS(Documents!$B:$B,A48,Documents!$J:$J,">0")
A49: Mission Planner | B49: Mission, operator, and fleet tools | C49: L4 | D49: Not stated in report | E49: Air, ground, water | F49: Open source | G49: Active | I49: Yes | J49: Yes | K49: Batch 3 | L49: =COUNTIF(Documents!$B:$B,A49) | M49: =COUNTIFS(Documents!$B:$B,A49,Documents!$J:$J,">0")
...

Sheet Documents
A1: Doc ID | B1: Technology | C1: Document title | D1: Document type | E1: URL | F1: Format | G1: Access | H1: Scrape method | I1: Priority | J1: Top 3 rank | K1: Verified | L1: What it covers / notes
A2: D0001 | B2: PX4 Autopilot | C2: PX4-Autopilot README | D2: README | E2: https://github.com/PX4/PX4-Autopilot/blob/main/README.md | F2: Markdown | G2: Public | H2: GitHub README | I2: 1 | J2: 1 | K2: Seen in search results | L2: Overview, architecture (uORB publish/subscribe), build and simulation quick start, links to all guides.
A3: D0002 | B3: PX4 Autopilot | C3: PX4 User and Developer Guide (main branch) | D3: Documentation site | E3: https://docs.px4.io/main/en/ | F3: Web pages | G3: Public | H3: Documentation-site crawl | I3: 1 | J3: 2 | K3: Derived from a verified link (confirm before scraping) | L3: Full user and developer guide; crawl the main branch only to avoid duplicate versioned copies (v1.12–v1.16 also exist).
A4: D0003 | B4: PX4 Autopilot | C4: Multi-vehicle simulation with Gazebo | D4: Technical documentation | E4: https://docs.px4.io/main/en/sim_gazebo_gz/multi_vehicle_simulation | F4: Web page | G4: Public | H4: Web page to markdown | I4: 2 | J4: 3 | K4: Seen in search results | L4: How to spawn several PX4 instances in one Gazebo world, with ROS 2 name spaces.
A5: D0004 | B5: PX4 Autopilot | C5: Multi-vehicle simulation with ROS 2 (v1.14) | D5: Technical documentation | E5: https://docs.px4.io/v1.14/en/ros/ros2_multi_vehicle | F5: Web page | G5: Public | H5: Web page to markdown | I5: 2 | K5: Seen in search results | L5: Instance numbering, DDS keys, and name-space rules for multi-vehicle ROS 2; older version, check for a main-branch equivalent.
A6: D0005 | B6: PX4 Autopilot | C6: PX4 guide source files (Markdown) | D6: Documentation source repository | E6: https://github.com/PX4/PX4-user_guide | F6: Markdown repository | G6: Public | H6: Git clone (docs folder) | I6: 2 | K6: Seen in search results | L6: Markdown source of the guide; cloning the en/ folder is cleaner than crawling HTML. Confirm the repository is still the live source.
A7: D0006 | B7: ArduPilot | C7: ArduPilot README | D7: README | E7: https://github.com/ArduPilot/ardupilot/blob/master/README.md | F7: Markdown | G7: Public | H7: GitHub README | I7: 1 | J7: 1 | K7: Seen in search results | L7: Project overview, vehicle types, contribution links.
A8: D0007 | B8: ArduPilot | C8: ArduPilot Development Site | D8: Documentation site | E8: https://ardupilot.org/dev/ | F8: Web pages | G8: Public | H8: Documentation-site crawl | I8: 1 | J8: 2 | K8: Seen in search results | L8: Developer wiki: building, SITL simulation, companion computers, MAVLink interfacing, ROS 2. Restrict crawl to /dev/.
A9: D0008 | B9: ArduPilot | C9: Learning the ArduPilot Codebase | D9: Technical documentation | E9: https://ardupilot.org/dev/docs/learning-the-ardupilot-codebase.html | F9: Web page | G9: Public | H9: Web page to markdown | I9: 2 | J9: 3 | K9: Seen in search results | L9: Architecture tutorial for the roughly 700,000-line codebase.
A10: D0009 | B10: ArduPilot | C10: ArduPilot documentation source (wiki repository) | D10: Documentation source repository | E10: https://github.com/ArduPilot/ardupilot_wiki | F10: reStructuredText repository | G10: Public | H10: Git clone (docs folder) | I10: 2 | K10: Derived from a verified link (confirm before scraping) | L10: Source of ardupilot.org wikis; the URL was seen only as a fork, so confirm the upstream path.
A11: D0010 | B11: Skybrush ArduPilot fork | C11: Skybrush Firmware developer documentation | D11: Documentation site | E11: https://docs.skybrush.io/public/skybrush-firmware-doc/latest/index.html | F11: Web pages | G11: Public | H11: Documentation-site crawl | I11: 1 | J11: 1 | K11: Seen in search results | L11: Documentation of the swarm-hardened ArduPilot fork.
A12: D0011 | B12: Skybrush ArduPilot fork | C12: Firmware update: ArduCopter 4.6.2 (compact telemetry, addressing over 250 drones) | D12: Release notes | E12: https://skybrush.io/blog/2025-10-20-firmware-update/ | F12: Web page | G12: Public | H12: Web page to markdown | I12: 1 | J12: 2 | K12: Seen in search results | L12: Explains the SHOW_GROUP parameter that extends MAVLink addressing and the compact telemetry profile.
A13: D0012 | B13: Crazyflie firmware | C13: crazyflie-firmware README | D13: README | E13: https://github.com/bitcraze/crazyflie-firmware | F13: Markdown | G13: Public | H13: GitHub README | I13: 1 | J13: 1 | K13: Seen in search results | L13: Build and docs pointers; forks state LGPL-3.0 (report says GPL-3).
A14: D0013 | B14: Crazyflie firmware | C14: crazyflie-firmware releases | D14: Release notes | E14: https://github.com/bitcraze/crazyflie-firmware/releases | F14: Web page | G14: Public | H14: GitHub releases API | I14: 3 | J14: 2 | K14: Seen in search results | L14: API and parameter removals by release.
A15: D0014 | B15: Crazyflie firmware | C15: Running Tapestry OS on the Crazyflie (Bitcraze blog, Sept 2026) | D15: Blog post | E15: https://www.bitcraze.io/2026/09/running-tapestry-os-on-the-crazyflie-collective-behavior-without-writing-firmware/ | F15: Web page | G15: Public | H15: Web page to markdown | I15: 2 | J15: 3 | K15: Seen in search results | L15: New Zephyr-based decentralized coordination stack; not in the report.
A16: D0015 | B16: Betaflight | C16: Betaflight README | D16: README | E16: https://github.com/betaflight/betaflight | F16: Markdown | G16: Public | H16: GitHub README | I16: 2 | J16: 1 | K16: From general knowledge, not seen this session (confirm before scraping) | L16: Low priority for swarm work.
A17: D0016 | B17: iNav | C17: iNav README | D17: README | E17: https://github.com/iNavFlight/inav | F17: Markdown | G17: Public | H17: GitHub README | I17: 2 | J17: 1 | K17: From general knowledge, not seen this session (confirm before scraping) | L17: Low priority for swarm work.
A18: D0017 | B18: PX4 DDS bridge (uXRCE-DDS) | C18: uXRCE-DDS (PX4-ROS 2/DDS Bridge) | D18: Technical documentation | E18: https://docs.px4.io/main/en/middleware/uxrce_dds | F18: Web page | G18: Public | H18: Web page to markdown | I18: 1 | J18: 1 | K18: Seen in search results | L18: Architecture, multi-vehicle keys and domain IDs, message routing.
A19: D0018 | B19: PX4 DDS bridge (uXRCE-DDS) | C19: PX4 ROS 2 User Guide | D19: Technical documentation | E19: https://docs.px4.io/main/en/ros2/user_guide | F19: Web page | G19: Public | H19: Web page to markdown | I19: 1 | J19: 2 | K19: Seen in search results | L19: PX4 now also offers a native Zenoh bridge (zenoh-pico client plus zenohd router), which the report does not mention.
A20: D0019 | B20: MRS UAV System | C20: MRS UAV System README | D20: README | E20: https://github.com/ctu-mrs/mrs_uav_system | F20: Markdown | G20: Public | H20: GitHub README | I20: 1 | J20: 1 | K20: Seen in search results | L20: Entry point; supported platforms, Docker images, documentation caveats.
A21: D0020 | B21: MRS UAV System | C21: The MRS UAV System: Pushing the Frontiers of Reproducible Research (arXiv 2008.08050) | D21: Paper | E21: https://arxiv.org/abs/2008.08050 | F21: PDF | G21: Public | H21: arXiv paper | I21: 1 | J21: 2 | K21: Derived from a verified link (confirm before scraping) | L21: Control and estimation architecture; identifier taken from a README citation.
A22: D0021 | B22: MRS UAV System | C22: MRS documentation site | D22: Documentation site | E22: https://ctu-mrs.github.io/ | F22: Web pages | G22: Public | H22: Documentation-site crawl | I22: 1 | J22: 3 | K22: Seen in search results | L22: Official documentation; maintainers say it is incomplete, so also pull package READMEs.
A23: D0022 | B23: MRS UAV System | C23: MRS documentation source | D23: Documentation source repository | E23: https://github.com/ctu-mrs/ctu-mrs.github.io | F23: Markdown repository | G23: Public | H23: Git clone (docs folder) | I23: 2 | K23: Derived from a verified link (confirm before scraping) | L23: Docs source including plugin-interface pages; confirm the path.
A24: D0023 | B24: Nav2 | C24: Nav2 README | D24: README | E24: https://github.com/ros-navigation/navigation2 | F24: Markdown | G24: Public | H24: GitHub README | I24: 1 | J24: 1 | K24: Derived from a verified link (confirm before scraping) | L24: Repository entry point; seen under its former organization name ros-planning.
A25: D0024 | B25: Nav2 | C25: Nav2 documentation | D25: Documentation site | E25: https://docs.nav2.org/ | F25: Web pages | G25: Public | H25: Documentation-site crawl | I25: 1 | J25: 2 | K25: Seen in search results | L25: Concepts, configuration, tutorials.
A26: D0025 | B26: Nav2 | C26: Nav2 documentation source | D26: Documentation source repository | E26: https://github.com/ros-navigation/docs.nav2.org | F26: Markdown repository | G26: Public | H26: Git clone (docs folder) | I26: 1 | J26: 3 | K26: Seen in search results | L26: Source of docs.nav2.org.
A27: D0026 | B27: Nav2 | C27: nav2_bringup README (multi-robot simulation) | D27: README | E27: https://github.com/ros-planning/navigation2/blob/main/nav2_bringup/README.md | F27: Markdown | G27: Public | H27: GitHub README | I27: 2 | K27: Seen in search results | L27: How to launch multiple robots, the report's point about name spaces.
A28: D0027 | B28: MOOS-IvP | C28: An Overview of MOOS-IvP and a Users Guide to the IvP Helm (Release 24.8) | D28: Technical documentation | E28: https://oceanai.mit.edu/moos-ivp-pdf/moosivp-helm.pdf | F28: PDF | G28: Public | H28: Direct PDF | I28: 1 | J28: 1 | K28: Seen in search results | L28: Definitive user guide, current release.
A29: D0028 | B29: MOOS-IvP | C29: Nested Autonomy for Unmanned Marine Vehicles with MOOS-IvP (Journal of Field Robotics, 2010) | D29: Paper | E29: https://apps.dtic.mil/sti/tr/pdf/ADA559856.pdf | F29: PDF | G29: Public | H29: Direct PDF | I29: 1 | J29: 2 | K29: Seen in search results | L29: Open copy on DTIC of the nested-autonomy paper.
A30: D0029 | B30: MOOS-IvP | C30: MOOS-IvP project site | D30: Documentation site | E30: https://oceanai.mit.edu/moos-ivp/pmwiki/pmwiki.php | F30: Web pages | G30: Public | H30: Documentation-site crawl | I30: 1 | J30: 3 | K30: Checked live on 22 September 2026 (URL corrected) | L30: Project home; the report's source list gives moos-ivp.org. URL corrected after live test: moos-ivp.org fails TLS verification (incomplete certificate chain) and redirects here over HTTP (was https://moos-ivp.org).
A31: D0030 | B31: MOOS-IvP | C31: MOOS-IvP GitHub repository | D31: README | E31: https://github.com/moos-ivp/moos-ivp | F31: Markdown | G31: Public | H31: GitHub README | I31: 2 | K31: Listed in the project report's sources (confirm before scraping) | L31: From the report's source list.
A32: D0031 | B32: MOOS-IvP | C32: Nested autonomy paper (Wiley) | D32: Paper | E32: https://onlinelibrary.wiley.com/doi/abs/10.1002/rob.20370 | F32: PDF | G32: Subscription (Wiley) | H32: Manual collection | I32: 3 | K32: Seen in search results | L32: Publisher version; the DTIC copy is sufficient.
A33: D0032 | B33: Autoware | C33: Autoware documentation | D33: Documentation site | E33: https://autowarefoundation.github.io/autoware-documentation/ | F33: Web pages | G33: Public | H33: Documentation-site crawl | I33: 1 | J33: 1 | K33: From general knowledge, not seen this session (confirm before scraping) | L33: Road-vehicle autonomy stack.
A34: D0033 | B34: Autoware | C34: Autoware README | D34: README | E34: https://github.com/autowarefoundation/autoware | F34: Markdown | G34: Public | H34: GitHub README | I34: 2 | J34: 2 | K34: From general knowledge, not seen this session (confirm before scraping) | L34: Repository entry point.
A35: D0034 | B35: NVIDIA Isaac ROS | C35: Isaac ROS documentation | D35: Documentation site | E35: https://nvidia-isaac-ros.github.io/ | F35: Web pages | G35: Public | H35: Documentation-site crawl | I35: 1 | J35: 1 | K35: Listed in the project report's sources (confirm before scraping) | L35: Report lists nvidia-isaac-ros.github.io/releases; crawl the current release only (versioned copies exist).
A36: D0035 | B36: NVIDIA Isaac ROS | C36: Isaac ROS Visual SLAM README | D36: README | E36: https://github.com/NVIDIA-ISAAC-ROS/isaac_ros_visual_slam | F36: Markdown | G36: Public | H36: GitHub README | I36: 1 | J36: 2 | K36: Seen in search results | L36: GPU visual-inertial odometry for navigation without satellite positioning.
A37: D0036 | B37: NVIDIA Isaac ROS | C37: Isaac ROS Nvblox README | D37: README | E37: https://github.com/NVIDIA-ISAAC-ROS/isaac_ros_nvblox | F37: Markdown | G37: Public | H37: GitHub README | I37: 1 | J37: 3 | K37: Seen in search results | L37: 3D reconstruction and Nav2 costmaps.
A38: D0037 | B38: cuVSLAM | C38: cuVSLAM README | D38: README | E38: https://github.com/nvidia-isaac/cuVSLAM | F38: Markdown | G38: Public | H38: GitHub README | I38: 1 | J38: 1 | K38: Seen in search results | L38: Standalone library, Python wheel, ROS 2 support.
A39: D0038 | B39: cuVSLAM | C39: cuVSLAM concepts (Isaac ROS 2.1 docs) | D39: Technical documentation | E39: https://nvidia-isaac-ros.github.io/v/release-2.1/concepts/visual_slam/cuvslam/index.html | F39: Web page | G39: Public | H39: Web page to markdown | I39: 2 | J39: 2 | K39: Seen in search results | L39: How tracking, landmarks, and loop closure work; older release.
A40: D0039 | B40: nvblox | C40: Isaac ROS Nvblox documentation | D40: Technical documentation | E40: https://nvidia-isaac-ros.github.io/v/release-3.1/repositories_and_packages/isaac_ros_nvblox/index.html | F40: Web page | G40: Public | H40: Web page to markdown | I40: 1 | J40: 1 | K40: Seen in search results | L40: Modes, timings, compatibility.
...

Sheet Techniques
A1: Technique | B1: Group | C1: Authoritative reference | D1: URL | E1: Reference type | F1: Verified
A2: Software-in-the-loop testing | B2: Simulation and testing | C2: PX4 simulation documentation | D2: https://docs.px4.io/main/en/simulation/ | E2: Documentation | F2: From general knowledge, not seen this session (confirm before scraping)
A3: Hardware-in-the-loop testing | B3: Simulation and testing | C3: PX4 hardware-in-the-loop simulation | D3: https://docs.px4.io/main/en/simulation/hitl.html | E3: Documentation | F3: From general knowledge, not seen this session (confirm before scraping)
A4: Sim-to-real transfer | B4: Simulation and testing | C4: Sim-to-Real Transfer in Deep RL for Robotics: a Survey (arXiv 2009.13303) | D4: https://arxiv.org/abs/2009.13303 | E4: Survey | F4: From general knowledge, not seen this session (confirm before scraping)
A5: Domain randomization | B5: Simulation and testing | C5: Domain Randomization for Transferring Deep Neural Networks from Simulation to the Real World (arXiv 1703.06907) | D5: https://arxiv.org/abs/1703.06907 | E5: Foundational paper | F5: From general knowledge, not seen this session (confirm before scraping)
A6: System identification | B6: Simulation and testing | C6: System identification (overview) | D6: https://en.wikipedia.org/wiki/System_identification | E6: Overview | F6: From general knowledge, not seen this session (confirm before scraping)
A7: Digital twins | B7: Simulation and testing | C7: Toward Digital Network Twins: Integrating Sionna RT in ns-3 (arXiv 2501.00372) | D7: https://arxiv.org/abs/2501.00372 | E7: Applied paper | F7: Seen in search results
A8: Gaussian-splatting rendering | B8: Simulation and testing | C8: 3D Gaussian Splatting for Real-Time Radiance Field Rendering (arXiv 2308.04079) | D8: https://arxiv.org/abs/2308.04079 | E8: Foundational paper | F8: From general knowledge, not seen this session (confirm before scraping)
A9: Ray tracing (radio and optical) | B9: Simulation and testing | C9: Sionna RT documentation (links technical report) | D9: https://nvlabs.github.io/sionna/rt | E9: Documentation | F9: Seen in search results
A10: Navigation without satellite positioning | B10: Navigation and perception | C10: Isaac ROS Visual SLAM README | D10: https://github.com/NVIDIA-ISAAC-ROS/isaac_ros_visual_slam | E10: Documentation | F10: Seen in search results
A11: Visual simultaneous localization and mapping | B11: Navigation and perception | C11: ORB-SLAM3 (arXiv 2007.11898) | D11: https://arxiv.org/abs/2007.11898 | E11: Foundational paper | F11: From general knowledge, not seen this session (confirm before scraping)
A12: Distributed simultaneous localization and mapping | B12: Navigation and perception | C12: Kimera-Multi (arXiv 2106.14386) | D12: https://arxiv.org/abs/2106.14386 | E12: Foundational paper | F12: From general knowledge, not seen this session (confirm before scraping)
... A59: Mobile recharging | B59: Operations | C59: Congestion Analysis for the DARPA OFFSET CCAST Swarm (battery and recovery logistics) | D59: https://arxiv.org/abs/2307.16788 | E59: Applied paper | F59: Seen in search results

Sheet Scrape methods
A1: Scrape method | B1: How to collect | C1: Output
A2: GitHub README | B2: Fetch the raw file (raw.githubusercontent.com/<owner>/<repo>/<branch>/README.md) or use the GitHub API README endpoint. Record the commit hash. | C2: Markdown as-is
A3: Git clone (docs folder) | B3: Shallow clone and keep only the documentation folder (Markdown or reStructuredText). Usually cleaner than crawling the rendered site. | C3: Markdown; convert reStructuredText with Pandoc
A4: GitHub releases API | B4: Call the GitHub releases API and store each release body with its tag and date. | C4: Markdown, one file per release or one combined file
A5: GitHub organization listing, then READMEs | B5: List repositories in the organization via the API, filter by relevance, then fetch each README. | C5: Markdown
A6: Documentation-site crawl | B6: First check /llms.txt or /llms-full.txt; then sitemap.xml; otherwise a same-domain crawl limited to the URL prefix given. Pin one version for versioned docs. Strip navigation chrome. | C6: HTML converted to Markdown, one file per page
A7: arXiv paper | B7: Use the arXiv identifier: fetch the PDF (arxiv.org/pdf/<id>) and metadata from the arXiv API. The HTML version, when available, extracts more cleanly than the PDF. | C7: Extracted text plus metadata
A8: Direct PDF | B8: Download and extract text (for example with PyMuPDF); keep the original PDF alongside. | C8: Extracted text plus original PDF
A9: Web page to markdown | B9: Fetch a single page and convert the main content to Markdown (for example with trafilatura or Readability). | C9: Markdown
A10: Manual collection | B10: Paywalled, gated, internal, or bot-blocked. Obtain through a subscription, vendor relationship, internal channel, or an open-access copy, then drop into the ingest folder. | C10: Whatever is obtained
